Workbook

Sheet MATRIZ CARTA
E5: CARTA | K5: SUGERIDO COSTOS | N5: PRECIO FINAL
B6: ADICIONES | C6: DESCRIPCION | D6: COSTO | E6: VENTA | F6: ICO 8% | G6: BASE | H6: % | I6: RENTABILIDAD | J6: ROTACION | K6: PRECIO SUGERIDO | L6: ICO2 | M6: CARTA | N6: PRECIO N | O6: ICO 8%2 | P6: CARTA | Q6: % | R6: RATION
A7: 1 | B7: =+ADICIONES!A6 -> ACEITUNA | D7: =+ADICIONES!J9 -> 828.933 | E7: =+ADICIONES!J10 -> 4900 | F7: =+E7/1.08*0.08 -> 362.96296 | G7: =+Tabla551857211411[[#This Row],[VENTA]]-Tabla551857211411[[#This Row],[ICO 8%]] -> 4537.037 | H7: =+Tabla551857211411[[#This Row],[COSTO]]/Tabla551857211411[[#This Row],[BASE]] -> 0.1827036 | I7: =+Tabla551857211411[[#This Row],[BASE]]/Tabla551857211411[[#This Row],[COSTO]] -> 5.4733459 | J7: =+VLOOKUP(Tabla551857211411[[#This Row],[ADICIONES]],Tabla77[#All],3,0) -> #N/A | K7: =+D7/(100-70)*100 -> 2763.11 | L7: =+K7/1.08*0.08 -> 204.67481 | M7: =+Tabla551857211411[[#This Row],[PRECIO SUGERIDO]]+Tabla551857211411[[#This Row],[ICO2]] -> 2967.7848 | O7: =+N7/1.08*0.08 -> 0 | P7: =+Tabla551857211411[[#This Row],[PRECIO N]]-Tabla551857211411[[#This Row],[ICO 8%2]] -> 0 | Q7: =+Tabla551857211411[[#This Row],[COSTO]]/Tabla551857211411[[#This Row],[CARTA]] -> #DIV/0! | R7: =+Tabla551857211411[[#This Row],[PRECIO N]]/Tabla551857211411[[#This Row],[COSTO]] -> 0
A8: 2 | B8: =+ADICIONES!A18 -> ADICION CANCHA Y CHIPS | D8: =+ADICIONES!J21 -> 986.50335 | E8: =+ADICIONES!J22 -> 4900 | F8: =+E8/1.08*0.08 -> 362.96296 | G8: =+Tabla551857211411[[#This Row],[VENTA]]-Tabla551857211411[[#This Row],[ICO 8%]] -> 4537.037 | H8: =+Tabla551857211411[[#This Row],[COSTO]]/Tabla551857211411[[#This Row],[BASE]] -> 0.21743339 | I8: =+Tabla551857211411[[#This Row],[BASE]]/Tabla551857211411[[#This Row],[COSTO]] -> 4.5991096 | J8: =+VLOOKUP(Tabla551857211411[[#This Row],[ADICIONES]],Tabla77[#All],3,0) -> 50 | K8: =+D8/(100-70)*100 -> 3288.3445 | L8: =+K8/1.08*0.08 -> 243.58108 | M8: =+Tabla551857211411[[#This Row],[PRECIO SUGERIDO]]+Tabla551857211411[[#This Row],[ICO2]] -> 3531.9256 | O8: =+N8/1.08*0.08 -> 0 | P8: =+Tabla551857211411[[#This Row],[PRECIO N]]-Tabla551857211411[[#This Row],[ICO 8%2]] -> 0 | Q8: =+Tabla551857211411[[#This Row],[COSTO]]/Tabla551857211411[[#This Row],[CARTA]] -> #DIV/0! | R8: =+Tabla551857211411[[#This Row],[PRECIO N]]/Tabla551857211411[[#This Row],[COSTO]] -> 0
A9: 3 | B9: =+ADICIONES!A30 -> AGUACATE | D9: =+ADICIONES!J33 -> 2778.3 | E9: =+ADICIONES!J34 -> 2500 | F9: =+E9/1.08*0.08 -> 185.18519 | G9: =+Tabla551857211411[[#This Row],[VENTA]]-Tabla551857211411[[#This Row],[ICO 8%]] -> 2314.8148 | H9: =+Tabla551857211411[[#This Row],[COSTO]]/Tabla551857211411[[#This Row],[BASE]] -> 1.2002256 | I9: =+Tabla551857211411[[#This Row],[BASE]]/Tabla551857211411[[#This Row],[COSTO]] -> 0.8331767 | J9: =+VLOOKUP(Tabla551857211411[[#This Row],[ADICIONES]],Tabla77[#All],3,0) -> 45 | K9: =+D9/(100-70)*100 -> 9261 | L9: =+K9/1.08*0.08 -> 686 | M9: =+Tabla551857211411[[#This Row],[PRECIO SUGERIDO]]+Tabla551857211411[[#This Row],[ICO2]] -> 9947 | O9: =+N9/1.08*0.08 -> 0 | P9: =+Tabla551857211411[[#This Row],[PRECIO N]]-Tabla551857211411[[#This Row],[ICO 8%2]] -> 0 | Q9: =+Tabla551857211411[[#This Row],[COSTO]]/Tabla551857211411[[#This Row],[CARTA]] -> #DIV/0! | R9: =+Tabla551857211411[[#This Row],[PRECIO N]]/Tabla551857211411[[#This Row],[COSTO]] -> 0
A10: 4 | B10: =+ADICIONES!A41 -> ARROZ BLANCO | D10: =+ADICIONES!J44 -> 911.00442 | E10: =+ADICIONES!J45 -> 8000 | F10: =+E10/1.08*0.08 -> 592.59259 | G10: =+Tabla551857211411[[#This Row],[VENTA]]-Tabla551857211411[[#This Row],[ICO 8%]] -> 7407.4074 | H10: =+Tabla551857211411[[#This Row],[COSTO]]/Tabla551857211411[[#This Row],[BASE]] -> 0.1229856 | I10: =+Tabla551857211411[[#This Row],[BASE]]/Tabla551857211411[[#This Row],[COSTO]] -> 8.1310334 | J10: =+VLOOKUP(Tabla551857211411[[#This Row],[ADICIONES]],Tabla77[#All],3,0) -> 1320 | K10: =+D10/(100-70)*100 -> 3036.6814 | L10: =+K10/1.08*0.08 -> 224.93936 | M10: =+Tabla551857211411[[#This Row],[PRECIO SUGERIDO]]+Tabla551857211411[[#This Row],[ICO2]] -> 3261.6208 | O10: =+N10/1.08*0.08 -> 0 | P10: =+Tabla551857211411[[#This Row],[PRECIO N]]-Tabla551857211411[[#This Row],[ICO 8%2]] -> 0 | Q10: =+Tabla551857211411[[#This Row],[COSTO]]/Tabla551857211411[[#This Row],[CARTA]] -> #DIV/0! | R10: =+Tabla551857211411[[#This Row],[PRECIO N]]/Tabla551857211411[[#This Row],[COSTO]] -> 0
A11: 5 | B11: =+ADICIONES!A54 -> ARROZ CREMOSO ADC | D11: =+ADICIONES!J57 -> 5609.736 | E11: =+ADICIONES!J58 -> 0 | F11: =+E11/1.08*0.08 -> 0 | G11: =+Tabla551857211411[[#This Row],[VENTA]]-Tabla551857211411[[#This Row],[ICO 8%]] -> 0 | H11: =+Tabla551857211411[[#This Row],[COSTO]]/Tabla551857211411[[#This Row],[BASE]] -> #DIV/0! | I11: =+Tabla551857211411[[#This Row],[BASE]]/Tabla551857211411[[#This Row],[COSTO]] -> 0 | J11: =+VLOOKUP(Tabla551857211411[[#This Row],[ADICIONES]],Tabla77[#All],3,0) -> 612 | K11: =+D11/(100-70)*100 -> 18699.12 | L11: =+K11/1.08*0.08 -> 1385.12 | M11: =+Tabla551857211411[[#This Row],[PRECIO SUGERIDO]]+Tabla551857211411[[#This Row],[ICO2]] -> 20084.24 | O11: =+N11/1.08*0.08 -> 0 | P11: =+Tabla551857211411[[#This Row],[PRECIO N]]-Tabla551857211411[[#This Row],[ICO 8%2]] -> 0 | Q11: =+Tabla551857211411[[#This Row],[COSTO]]/Tabla551857211411[[#This Row],[CARTA]] -> #DIV/0! | R11: =+Tabla551857211411[[#This Row],[PRECIO N]]/Tabla551857211411[[#This Row],[COSTO]] -> 0
A12: 6 | B12: =+ADICIONES!A66 -> CAMARON | D12: =+ADICIONES!J69 -> 3570 | E12: =+ADICIONES!J70 -> 10000 | F12: =+E12/1.08*0.08 -> 740.74074 | G12: =+Tabla551857211411[[#This Row],[VENTA]]-Tabla551857211411[[#This Row],[ICO 8%]] -> 9259.2593 | H12: =+Tabla551857211411[[#This Row],[COSTO]]/Tabla551857211411[[#This Row],[BASE]] -> 0.38556 | I12: =+Tabla551857211411[[#This Row],[BASE]]/Tabla551857211411[[#This Row],[COSTO]] -> 2.59363 | J12: =+VLOOKUP(Tabla551857211411[[#This Row],[ADICIONES]],Tabla77[#All],3,0) -> 8 | K12: =+D12/(100-70)*100 -> 11900 | L12: =+K12/1.08*0.08 -> 881.48148 | M12: =+Tabla551857211411[[#This Row],[PRECIO SUGERIDO]]+Tabla551857211411[[#This Row],[ICO2]] -> 12781.481 | O12: =+N12/1.08*0.08 -> 0 | P12: =+Tabla551857211411[[#This Row],[PRECIO N]]-Tabla551857211411[[#This Row],[ICO 8%2]] -> 0 | Q12: =+Tabla551857211411[[#This Row],[COSTO]]/Tabla551857211411[[#This Row],[CARTA]] -> #DIV/0! | R12: =+Tabla551857211411[[#This Row],[PRECIO N]]/Tabla551857211411[[#This Row],[COSTO]] -> 0
A13: 7 | B13: =+ADICIONES!A80 -> CAMOTE | D13: =+ADICIONES!J83 -> 1250.4377 | E13: =+ADICIONES!J84 -> 5000 | F13: =+E13/1.08*0.08 -> 370.37037 | G13: =+Tabla551857211411[[#This Row],[VENTA]]-Tabla551857211411[[#This Row],[ICO 8%]] -> 4629.6296 | H13: =+Tabla551857211411[[#This Row],[COSTO]]/Tabla551857211411[[#This Row],[BASE]] -> 0.27009454 | I13: =+Tabla551857211411[[#This Row],[BASE]]/Tabla551857211411[[#This Row],[COSTO]] -> 3.7024074 | J13: =+VLOOKUP(Tabla551857211411[[#This Row],[ADICIONES]],Tabla77[#All],3,0) -> 3 | K13: =+D13/(100-70)*100 -> 4168.1256 | L13: =+K13/1.08*0.08 -> 308.75004 | M13: =+Tabla551857211411[[#This Row],[PRECIO SUGERIDO]]+Tabla551857211411[[#This Row],[ICO2]] -> 4476.8756 | O13: =+N13/1.08*0.08 -> 0 | P13: =+Tabla551857211411[[#This Row],[PRECIO N]]-Tabla551857211411[[#This Row],[ICO 8%2]] -> 0 | Q13: =+Tabla551857211411[[#This Row],[COSTO]]/Tabla551857211411[[#This Row],[CARTA]] -> #DIV/0! | R13: =+Tabla551857211411[[#This Row],[PRECIO N]]/Tabla551857211411[[#This Row],[COSTO]] -> 0
A14: 8 | B14: =+ADICIONES!A92 -> CEREZA | D14: =+ADICIONES!J95 -> 167.03912 | E14: =+ADICIONES!J96 -> 4900 | F14: =+E14/1.08*0.08 -> 362.96296 | G14: =+Tabla551857211411[[#This Row],[VENTA]]-Tabla551857211411[[#This Row],[ICO 8%]] -> 4537.037 | H14: =+Tabla551857211411[[#This Row],[COSTO]]/Tabla551857211411[[#This Row],[BASE]] -> 0.036816785 | I14: =+Tabla551857211411[[#This Row],[BASE]]/Tabla551857211411[[#This Row],[COSTO]] -> 27.161524 | J14: =+VLOOKUP(Tabla551857211411[[#This Row],[ADICIONES]],Tabla77[#All],3,0) -> 2 | K14: =+D14/(100-70)*100 -> 556.79706 | L14: =+K14/1.08*0.08 -> 41.244227 | M14: =+Tabla551857211411[[#This Row],[PRECIO SUGERIDO]]+Tabla551857211411[[#This Row],[ICO2]] -> 598.04129 | O14: =+N14/1.08*0.08 -> 0 | P14: =+Tabla551857211411[[#This Row],[PRECIO N]]-Tabla551857211411[[#This Row],[ICO 8%2]] -> 0 | Q14: =+Tabla551857211411[[#This Row],[COSTO]]/Tabla551857211411[[#This Row],[CARTA]] -> #DIV/0! | R14: =+Tabla551857211411[[#This Row],[PRECIO N]]/Tabla551857211411[[#This Row],[COSTO]] -> 0
A15: 9 | B15: =+ADICIONES!A108 -> CHANCHO | D15: =+ADICIONES!J111 -> 5166.8431 | E15: =+ADICIONES!J112 -> 35000 | F15: =+E15/1.08*0.08 -> 2592.5926 | G15: =+Tabla551857211411[[#This Row],[VENTA]]-Tabla551857211411[[#This Row],[ICO 8%]] -> 32407.407 | H15: =+Tabla551857211411[[#This Row],[COSTO]]/Tabla551857211411[[#This Row],[BASE]] -> 0.15943402 | I15: =+Tabla551857211411[[#This Row],[BASE]]/Tabla551857211411[[#This Row],[COSTO]] -> 6.2721872 | J15: =+VLOOKUP(Tabla551857211411[[#This Row],[ADICIONES]],Tabla77[#All],3,0) -> #N/A | K15: =+D15/(100-70)*100 -> 17222.81 | L15: =+K15/1.08*0.08 -> 1275.7637 | M15: =+Tabla551857211411[[#This Row],[PRECIO SUGERIDO]]+Tabla551857211411[[#This Row],[ICO2]] -> 18498.574 | O15: =+N15/1.08*0.08 -> 0 | P15: =+Tabla551857211411[[#This Row],[PRECIO N]]-Tabla551857211411[[#This Row],[ICO 8%2]] -> 0 | Q15: =+Tabla551857211411[[#This Row],[COSTO]]/Tabla551857211411[[#This Row],[CARTA]] -> #DIV/0! | R15: =+Tabla551857211411[[#This Row],[PRECIO N]]/Tabla551857211411[[#This Row],[COSTO]] -> 0
A16: 10 | B16: =+ADICIONES!A120 -> ENSALADA | D16: =+ADICIONES!J123 -> 2012.019 | E16: =+ADICIONES!J124 -> 5500 | F16: =+E16/1.08*0.08 -> 407.40741 | G16: =+Tabla551857211411[[#This Row],[VENTA]]-Tabla551857211411[[#This Row],[ICO 8%]] -> 5092.5926 | H16: =+Tabla551857211411[[#This Row],[COSTO]]/Tabla551857211411[[#This Row],[BASE]] -> 0.39508736 | I16: =+Tabla551857211411[[#This Row],[BASE]]/Tabla551857211411[[#This Row],[COSTO]] -> 2.5310858 | J16: =+VLOOKUP(Tabla551857211411[[#This Row],[ADICIONES]],Tabla77[#All],3,0) -> 29 | K16: =+D16/(100-70)*100 -> 6706.7299 | L16: =+K16/1.08*0.08 -> 496.79481 | M16: =+Tabla551857211411[[#This Row],[PRECIO SUGERIDO]]+Tabla551857211411[[#This Row],[ICO2]] -> 7203.5247 | O16: =+N16/1.08*0.08 -> 0 | P16: =+Tabla551857211411[[#This Row],[PRECIO N]]-Tabla551857211411[[#This Row],[ICO 8%2]] -> 0 | Q16: =+Tabla551857211411[[#This Row],[COSTO]]/Tabla551857211411[[#This Row],[CARTA]] -> #DIV/0! | R16: =+Tabla551857211411[[#This Row],[PRECIO N]]/Tabla551857211411[[#This Row],[COSTO]] -> 0
A17: 11 | B17: =+ADICIONES!A135 -> FILETE DE POLLO | D17: =+ADICIONES!J137 -> 2169.9999 | E17: =+ADICIONES!J138 -> 9000 | F17: =+E17/1.08*0.08 -> 666.66667 | G17: =+Tabla551857211411[[#This Row],[VENTA]]-Tabla551857211411[[#This Row],[ICO 8%]] -> 8333.3333 | H17: =+Tabla551857211411[[#This Row],[COSTO]]/Tabla551857211411[[#This Row],[BASE]] -> 0.26039999 | I17: =+Tabla551857211411[[#This Row],[BASE]]/Tabla551857211411[[#This Row],[COSTO]] -> 3.8402459 | J17: =+VLOOKUP(Tabla551857211411[[#This Row],[ADICIONES]],Tabla77[#All],3,0) -> 5 | K17: =+D17/(100-70)*100 -> 7233.3332 | L17: =+K17/1.08*0.08 -> 535.80246 | M17: =+Tabla551857211411[[#This Row],[PRECIO SUGERIDO]]+Tabla551857211411[[#This Row],[ICO2]] -> 7769.1356 | O17: =+N17/1.08*0.08 -> 0 | P17: =+Tabla551857211411[[#This Row],[PRECIO N]]-Tabla551857211411[[#This Row],[ICO 8%2]] -> 0 | Q17: =+Tabla551857211411[[#This Row],[COSTO]]/Tabla551857211411[[#This Row],[CARTA]] -> #DIV/0! | R17: =+Tabla551857211411[[#This Row],[PRECIO N]]/Tabla551857211411[[#This Row],[COSTO]] -> 0
A18: 12 | B18: =+ADICIONES!A146 -> FILETE DE SALMON | D18: =+ADICIONES!J149 -> 0 | E18: =+ADICIONES!J150 -> 40000 | F18: =+E18/1.08*0.08 -> 2962.963 | G18: =+Tabla551857211411[[#This Row],[VENTA]]-Tabla551857211411[[#This Row],[ICO 8%]] -> 37037.037 | H18: =+Tabla551857211411[[#This Row],[COSTO]]/Tabla551857211411[[#This Row],[BASE]] -> 0 | I18: =+Tabla551857211411[[#This Row],[BASE]]/Tabla551857211411[[#This Row],[COSTO]] -> #DIV/0! | J18: =+VLOOKUP(Tabla551857211411[[#This Row],[ADICIONES]],Tabla77[#All],3,0) -> 2 | K18: =+D18/(100-70)*100 -> 0 | L18: =+K18/1.08*0.08 -> 0 | M18: =+Tabla551857211411[[#This Row],[PRECIO SUGERIDO]]+Tabla551857211411[[#This Row],[ICO2]] -> 0 | O18: =+N18/1.08*0.08 -> 0 | P18: =+Tabla551857211411[[#This Row],[PRECIO N]]-Tabla551857211411[[#This Row],[ICO 8%2]] -> 0 | Q18: =+Tabla551857211411[[#This Row],[COSTO]]/Tabla551857211411[[#This Row],[CARTA]] -> #DIV/0! | R18: =+Tabla551857211411[[#This Row],[PRECIO N]]/Tabla551857211411[[#This Row],[COSTO]] -> #DIV/0!
A19: 13 | B19: =+ADICIONES!A158 -> FILETE DE TILAPIA | D19: =+ADICIONES!J161 -> 5179.9999 | E19: =+ADICIONES!J162 -> 25000 | F19: =+E19/1.08*0.08 -> 1851.8519 | G19: =+Tabla551857211411[[#This Row],[VENTA]]-Tabla551857211411[[#This Row],[ICO 8%]] -> 23148.148 | H19: =+Tabla551857211411[[#This Row],[COSTO]]/Tabla551857211411[[#This Row],[BASE]] -> 0.22377599 | I19: =+Tabla551857211411[[#This Row],[BASE]]/Tabla551857211411[[#This Row],[COSTO]] -> 4.4687546 | J19: =+VLOOKUP(Tabla551857211411[[#This Row],[ADICIONES]],Tabla77[#All],3,0) -> 2 | K19: =+D19/(100-70)*100 -> 17266.666 | L19: =+K19/1.08*0.08 -> 1279.0123 | M19: =+Tabla551857211411[[#This Row],[PRECIO SUGERIDO]]+Tabla551857211411[[#This Row],[ICO2]] -> 18545.679 | O19: =+N19/1.08*0.08 -> 0 | P19: =+Tabla551857211411[[#This Row],[PRECIO N]]-Tabla551857211411[[#This Row],[ICO 8%2]] -> 0 | Q19: =+Tabla551857211411[[#This Row],[COSTO]]/Tabla551857211411[[#This Row],[CARTA]] -> #DIV/0! | R19: =+Tabla551857211411[[#This Row],[PRECIO N]]/Tabla551857211411[[#This Row],[COSTO]] -> 0
A20: 14 | B20: =+ADICIONES!A170 -> FRESA | D20: =+ADICIONES!J173 -> 361.66665 | E20: =+ADICIONES!J174 -> 4900 | F20: =+E20/1.08*0.08 -> 362.96296 | G20: =+Tabla551857211411[[#This Row],[VENTA]]-Tabla551857211411[[#This Row],[ICO 8%]] -> 4537.037 | H20: =+Tabla551857211411[[#This Row],[COSTO]]/Tabla551857211411[[#This Row],[BASE]] -> 0.079714281 | I20: =+Tabla551857211411[[#This Row],[BASE]]/Tabla551857211411[[#This Row],[COSTO]] -> 12.544804 | J20: =+VLOOKUP(Tabla551857211411[[#This Row],[ADICIONES]],Tabla77[#All],3,0) -> 1 | K20: =+D20/(100-70)*100 -> 1205.5555 | L20: =+K20/1.08*0.08 -> 89.300407 | M20: =+Tabla551857211411[[#This Row],[PRECIO SUGERIDO]]+Tabla551857211411[[#This Row],[ICO2]] -> 1294.8559 | O20: =+N20/1.08*0.08 -> 0 | P20: =+Tabla551857211411[[#This Row],[PRECIO N]]-Tabla551857211411[[#This Row],[ICO 8%2]] -> 0 | Q20: =+Tabla551857211411[[#This Row],[COSTO]]/Tabla551857211411[[#This Row],[CARTA]] -> #DIV/0! | R20: =+Tabla551857211411[[#This Row],[PRECIO N]]/Tabla551857211411[[#This Row],[COSTO]] -> 0
A21: 15 | B21: =+ADICIONES!A182 -> GUACAMOLE | D21: =+ADICIONES!J185 -> 781.33452 | E21: =+ADICIONES!J186 -> 2900 | F21: =+E21/1.08*0.08 -> 214.81481 | G21: =+Tabla551857211411[[#This Row],[VENTA]]-Tabla551857211411[[#This Row],[ICO 8%]] -> 2685.1852 | H21: =+Tabla551857211411[[#This Row],[COSTO]]/Tabla551857211411[[#This Row],[BASE]] -> 0.29097975 | I21: =+Tabla551857211411[[#This Row],[BASE]]/Tabla551857211411[[#This Row],[COSTO]] -> 3.4366652 | J21: =+VLOOKUP(Tabla551857211411[[#This Row],[ADICIONES]],Tabla77[#All],3,0) -> 7 | K21: =+D21/(100-70)*100 -> 2604.4484 | L21: =+K21/1.08*0.08 -> 192.9221 | M21: =+Tabla551857211411[[#This Row],[PRECIO SUGERIDO]]+Tabla551857211411[[#This Row],[ICO2]] -> 2797.3705 | O21: =+N21/1.08*0.08 -> 0 | P21: =+Tabla551857211411[[#This Row],[PRECIO N]]-Tabla551857211411[[#This Row],[ICO 8%2]] -> 0 | Q21: =+Tabla551857211411[[#This Row],[COSTO]]/Tabla551857211411[[#This Row],[CARTA]] -> #DIV/0! | R21: =+Tabla551857211411[[#This Row],[PRECIO N]]/Tabla551857211411[[#This Row],[COSTO]] -> 0
A22: 16 | B22: =+ADICIONES!A194 -> HELADO | D22: =+ADICIONES!J197 -> 780.2109 | E22: =+ADICIONES!J198 -> 12000 | F22: =+E22/1.08*0.08 -> 888.88889 | G22: =+Tabla551857211411[[#This Row],[VENTA]]-Tabla551857211411[[#This Row],[ICO 8%]] -> 11111.111 | H22: =+Tabla551857211411[[#This Row],[COSTO]]/Tabla551857211411[[#This Row],[BASE]] -> 0.070218981 | I22: =+Tabla551857211411[[#This Row],[BASE]]/Tabla551857211411[[#This Row],[COSTO]] -> 14.241164 | J22: =+VLOOKUP(Tabla551857211411[[#This Row],[ADICIONES]],Tabla77[#All],3,0) -> 8 | K22: =+D22/(100-70)*100 -> 2600.703 | L22: =+K22/1.08*0.08 -> 192.64467 | M22: =+Tabla551857211411[[#This Row],[PRECIO SUGERIDO]]+Tabla551857211411[[#This Row],[ICO2]] -> 2793.3477 | O22: =+N22/1.08*0.08 -> 0 | P22: =+Tabla551857211411[[#This Row],[PRECIO N]]-Tabla551857211411[[#This Row],[ICO 8%2]] -> 0 | Q22: =+Tabla551857211411[[#This Row],[COSTO]]/Tabla551857211411[[#This Row],[CARTA]] -> #DIV/0! | R22: =+Tabla551857211411[[#This Row],[PRECIO N]]/Tabla551857211411[[#This Row],[COSTO]] -> 0
A23: 17 | B23: =+ADICIONES!A207 -> HUEVO | D23: =+ADICIONES!J210 -> #N/A | E23: =+ADICIONES!J211 -> 1500 | F23: =+E23/1.08*0.08 -> 111.11111 | G23: =+Tabla551857211411[[#This Row],[VENTA]]-Tabla551857211411[[#This Row],[ICO 8%]] -> 1388.8889 | H23: =+Tabla551857211411[[#This Row],[COSTO]]/Tabla551857211411[[#This Row],[BASE]] -> #N/A | I23: =+Tabla551857211411[[#This Row],[BASE]]/Tabla551857211411[[#This Row],[COSTO]] -> #N/A | J23: =+VLOOKUP(Tabla551857211411[[#This Row],[ADICIONES]],Tabla77[#All],3,0) -> 229 | K23: =+D23/(100-70)*100 -> #N/A | L23: =+K23/1.08*0.08 -> #N/A | M23: =+Tabla551857211411[[#This Row],[PRECIO SUGERIDO]]+Tabla551857211411[[#This Row],[ICO2]] -> #N/A | O23: =+N23/1.08*0.08 -> 0 | P23: =+Tabla551857211411[[#This Row],[PRECIO N]]-Tabla551857211411[[#This Row],[ICO 8%2]] -> 0 | Q23: =+Tabla551857211411[[#This Row],[COSTO]]/Tabla551857211411[[#This Row],[CARTA]] -> #N/A | R23: =+Tabla551857211411[[#This Row],[PRECIO N]]/Tabla551857211411[[#This Row],[COSTO]] -> #N/A
A24: 18 | B24: =+ADICIONES!A221 -> LANGOSTINOS | D24: =+ADICIONES!J224 -> 6825 | E24: =+ADICIONES!J225 -> 25000 | F24: =+E24/1.08*0.08 -> 1851.8519 | G24: =+Tabla551857211411[[#This Row],[VENTA]]-Tabla551857211411[[#This Row],[ICO 8%]] -> 23148.148 | H24: =+Tabla551857211411[[#This Row],[COSTO]]/Tabla551857211411[[#This Row],[BASE]] -> 0.29484 | I24: =+Tabla551857211411[[#This Row],[BASE]]/Tabla551857211411[[#This Row],[COSTO]] -> 3.3916701 | J24: =+VLOOKUP(Tabla551857211411[[#This Row],[ADICIONES]],Tabla77[#All],3,0) -> 1 | K24: =+D24/(100-70)*100 -> 22750 | L24: =+K24/1.08*0.08 -> 1685.1852 | M24: =+Tabla551857211411[[#This Row],[PRECIO SUGERIDO]]+Tabla551857211411[[#This Row],[ICO2]] -> 24435.185 | O24: =+N24/1.08*0.08 -> 0 | P24: =+Tabla551857211411[[#This Row],[PRECIO N]]-Tabla551857211411[[#This Row],[ICO 8%2]] -> 0 | Q24: =+Tabla551857211411[[#This Row],[COSTO]]/Tabla551857211411[[#This Row],[CARTA]] -> #DIV/0! | R24: =+Tabla551857211411[[#This Row],[PRECIO N]]/Tabla551857211411[[#This Row],[COSTO]] -> 0
A25: 19 | B25: =+ADICIONES!A232 -> LECHE | D25: =+ADICIONES!J235 -> 2206.512 | E25: =+ADICIONES!J236 -> 2000 | F25: =+E25/1.08*0.08 -> 148.14815 | G25: =+Tabla551857211411[[#This Row],[VENTA]]-Tabla551857211411[[#This Row],[ICO 8%]] -> 1851.8519 | H25: =+Tabla551857211411[[#This Row],[COSTO]]/Tabla551857211411[[#This Row],[BASE]] -> 1.1915165 | I25: =+Tabla551857211411[[#This Row],[BASE]]/Tabla551857211411[[#This Row],[COSTO]] -> 0.83926661 | J25: =+VLOOKUP(Tabla551857211411[[#This Row],[ADICIONES]],Tabla77[#All],3,0) -> 11 | K25: =+D25/(100-70)*100 -> 7355.04 | L25: =+K25/1.08*0.08 -> 544.81778 | M25: =+Tabla551857211411[[#This Row],[PRECIO SUGERIDO]]+Tabla551857211411[[#This Row],[ICO2]] -> 7899.8578 | O25: =+N25/1.08*0.08 -> 0 | P25: =+Tabla551857211411[[#This Row],[PRECIO N]]-Tabla551857211411[[#This Row],[ICO 8%2]] -> 0 | Q25: =+Tabla551857211411[[#This Row],[COSTO]]/Tabla551857211411[[#This Row],[CARTA]] -> #DIV/0! | R25: =+Tabla551857211411[[#This Row],[PRECIO N]]/Tabla551857211411[[#This Row],[COSTO]] -> 0
A26: 20 | B26: =+ADICIONES!A245 -> LYCHE | D26: =+ADICIONES!J248 -> 1005.83 | E26: =+ADICIONES!J249 -> 4900 | F26: =+E26/1.08*0.08 -> 362.96296 | G26: =+Tabla551857211411[[#This Row],[VENTA]]-Tabla551857211411[[#This Row],[ICO 8%]] -> 4537.037 | H26: =+Tabla551857211411[[#This Row],[COSTO]]/Tabla551857211411[[#This Row],[BASE]] -> 0.22169314 | I26: =+Tabla551857211411[[#This Row],[BASE]]/Tabla551857211411[[#This Row],[COSTO]] -> 4.5107394 | J26: =+VLOOKUP(Tabla551857211411[[#This Row],[ADICIONES]],Tabla77[#All],3,0) -> 9 | K26: =+D26/(100-70)*100 -> 3352.7667 | L26: =+K26/1.08*0.08 -> 248.35309 | M26: =+Tabla551857211411[[#This Row],[PRECIO SUGERIDO]]+Tabla551857211411[[#This Row],[ICO2]] -> 3601.1198 | O26: =+N26/1.08*0.08 -> 0 | P26: =+Tabla551857211411[[#This Row],[PRECIO N]]-Tabla551857211411[[#This Row],[ICO 8%2]] -> 0 | Q26: =+Tabla551857211411[[#This Row],[COSTO]]/Tabla551857211411[[#This Row],[CARTA]] -> #DIV/0! | R26: =+Tabla551857211411[[#This Row],[PRECIO N]]/Tabla551857211411[[#This Row],[COSTO]] -> 0
A27: 21 | B27: =+ADICIONES!A257 -> MAYO ACEVICHADA | D27: =+ADICIONES!J260 -> 710.18289 | E27: =+ADICIONES!J261 -> 2900 | F27: =+E27/1.08*0.08 -> 214.81481 | G27: =+Tabla551857211411[[#This Row],[VENTA]]-Tabla551857211411[[#This Row],[ICO 8%]] -> 2685.1852 | H27: =+Tabla551857211411[[#This Row],[COSTO]]/Tabla551857211411[[#This Row],[BASE]] -> 0.2644819 | I27: =+Tabla551857211411[[#This Row],[BASE]]/Tabla551857211411[[#This Row],[COSTO]] -> 3.780977 | J27: =+VLOOKUP(Tabla551857211411[[#This Row],[ADICIONES]],Tabla77[#All],3,0) -> 15 | K27: =+D27/(100-70)*100 -> 2367.2763 | L27: =+K27/1.08*0.08 -> 175.3538 | M27: =+Tabla551857211411[[#This Row],[PRECIO SUGERIDO]]+Tabla551857211411[[#This Row],[ICO2]] -> 2542.6301 | O27: =+N27/1.08*0.08 -> 0 | P27: =+Tabla551857211411[[#This Row],[PRECIO N]]-Tabla551857211411[[#This Row],[ICO 8%2]] -> 0 | Q27: =+Tabla551857211411[[#This Row],[COSTO]]/Tabla551857211411[[#This Row],[CARTA]] -> #DIV/0! | R27: =+Tabla551857211411[[#This Row],[PRECIO N]]/Tabla551857211411[[#This Row],[COSTO]] -> 0
A28: 22 | B28: =+ADICIONES!A268 -> MEJILLONES | D28: =+ADICIONES!J271 -> 1699.32 | E28: =+ADICIONES!J272 -> 6000 | F28: =+E28/1.08*0.08 -> 444.44444 | G28: =+Tabla551857211411[[#This Row],[VENTA]]-Tabla551857211411[[#This Row],[ICO 8%]] -> 5555.5556 | H28: =+Tabla551857211411[[#This Row],[COSTO]]/Tabla551857211411[[#This Row],[BASE]] -> 0.3058776 | I28: =+Tabla551857211411[[#This Row],[BASE]]/Tabla551857211411[[#This Row],[COSTO]] -> 3.2692816 | J28: =+VLOOKUP(Tabla551857211411[[#This Row],[ADICIONES]],Tabla77[#All],3,0) -> #N/A | K28: =+D28/(100-70)*100 -> 5664.4 | L28: =+K28/1.08*0.08 -> 419.58519 | M28: =+Tabla551857211411[[#This Row],[PRECIO SUGERIDO]]+Tabla551857211411[[#This Row],[ICO2]] -> 6083.9852 | O28: =+N28/1.08*0.08 -> 0 | P28: =+Tabla551857211411[[#This Row],[PRECIO N]]-Tabla551857211411[[#This Row],[ICO 8%2]] -> 0 | Q28: =+Tabla551857211411[[#This Row],[COSTO]]/Tabla551857211411[[#This Row],[CARTA]] -> #DIV/0! | R28: =+Tabla551857211411[[#This Row],[PRECIO N]]/Tabla551857211411[[#This Row],[COSTO]] -> 0
A29: 23 | B29: =+ADICIONES!A279 -> MERMELADA DE AJI AMARILLO | D29: =+ADICIONES!J282 -> 900.37726 | E29: =+ADICIONES!J283 -> 3900 | F29: =+E29/1.08*0.08 -> 288.88889 | G29: =+Tabla551857211411[[#This Row],[VENTA]]-Tabla551857211411[[#This Row],[ICO 8%]] -> 3611.1111 | H29: =+Tabla551857211411[[#This Row],[COSTO]]/Tabla551857211411[[#This Row],[BASE]] -> 0.24933524 | I29: =+Tabla551857211411[[#This Row],[BASE]]/Tabla551857211411[[#This Row],[COSTO]] -> 4.0106645 | J29: =+VLOOKUP(Tabla551857211411[[#This Row],[ADICIONES]],Tabla77[#All],3,0) -> #N/A | K29: =+D29/(100-70)*100 -> 3001.2575 | L29: =+K29/1.08*0.08 -> 222.31537 | M29: =+Tabla551857211411[[#This Row],[PRECIO SUGERIDO]]+Tabla551857211411[[#This Row],[ICO2]] -> 3223.5729 | O29: =+N29/1.08*0.08 -> 0 | P29: =+Tabla551857211411[[#This Row],[PRECIO N]]-Tabla551857211411[[#This Row],[ICO 8%2]] -> 0 | Q29: =+Tabla551857211411[[#This Row],[COSTO]]/Tabla551857211411[[#This Row],[CARTA]] -> #DIV/0! | R29: =+Tabla551857211411[[#This Row],[PRECIO N]]/Tabla551857211411[[#This Row],[COSTO]] -> 0
A30: 24 | B30: =+ADICIONES!A292 -> PAPA A LA FRANCESA | D30: =+ADICIONES!J295 -> 2653.8727 | E30: =+ADICIONES!J296 -> 8000 | F30: =+E30/1.08*0.08 -> 592.59259 | G30: =+Tabla551857211411[[#This Row],[VENTA]]-Tabla551857211411[[#This Row],[ICO 8%]] -> 7407.4074 | H30: =+Tabla551857211411[[#This Row],[COSTO]]/Tabla551857211411[[#This Row],[BASE]] -> 0.35827281 | I30: =+Tabla551857211411[[#This Row],[BASE]]/Tabla551857211411[[#This Row],[COSTO]] -> 2.7911691 | J30: =+VLOOKUP(Tabla551857211411[[#This Row],[ADICIONES]],Tabla77[#All],3,0) -> 1164 | K30: =+D30/(100-70)*100 -> 8846.2423 | L30: =+K30/1.08*0.08 -> 655.27721 | M30: =+Tabla551857211411[[#This Row],[PRECIO SUGERIDO]]+Tabla551857211411[[#This Row],[ICO2]] -> 9501.5195 | O30: =+N30/1.08*0.08 -> 0 | P30: =+Tabla551857211411[[#This Row],[PRECIO N]]-Tabla551857211411[[#This Row],[ICO 8%2]] -> 0 | Q30: =+Tabla551857211411[[#This Row],[COSTO]]/Tabla551857211411[[#This Row],[CARTA]] -> #DIV/0! | R30: =+Tabla551857211411[[#This Row],[PRECIO N]]/Tabla551857211411[[#This Row],[COSTO]] -> 0
A31: 25 | B31: =+ADICIONES!A305 -> PAPA CRIOLLA | D31: =+ADICIONES!J308 -> 1400 | E31: =+ADICIONES!J309 -> 8000 | F31: =+E31/1.08*0.08 -> 592.59259 | G31: =+Tabla551857211411[[#This Row],[VENTA]]-Tabla551857211411[[#This Row],[ICO 8%]] -> 7407.4074 | H31: =+Tabla551857211411[[#This Row],[COSTO]]/Tabla551857211411[[#This Row],[BASE]] -> 0.189 | I31: =+Tabla551857211411[[#This Row],[BASE]]/Tabla551857211411[[#This Row],[COSTO]] -> 5.2910053 | J31: =+VLOOKUP(Tabla551857211411[[#This Row],[ADICIONES]],Tabla77[#All],3,0) -> 112 | K31: =+D31/(100-70)*100 -> 4666.6667 | L31: =+K31/1.08*0.08 -> 345.67901 | M31: =+Tabla551857211411[[#This Row],[PRECIO SUGERIDO]]+Tabla551857211411[[#This Row],[ICO2]] -> 5012.3457 | O31: =+N31/1.08*0.08 -> 0 | P31: =+Tabla551857211411[[#This Row],[PRECIO N]]-Tabla551857211411[[#This Row],[ICO 8%2]] -> 0 | Q31: =+Tabla551857211411[[#This Row],[COSTO]]/Tabla551857211411[[#This Row],[CARTA]] -> #DIV/0! | R31: =+Tabla551857211411[[#This Row],[PRECIO N]]/Tabla551857211411[[#This Row],[COSTO]] -> 0
A32: 26 | B32: =+ADICIONES!A316 -> PULPO | D32: =+ADICIONES!J319 -> 22002.947 | E32: =+ADICIONES!J320 -> 17000 | F32: =+E32/1.08*0.08 -> 1259.2593 | G32: =+Tabla551857211411[[#This Row],[VENTA]]-Tabla551857211411[[#This Row],[ICO 8%]] -> 15740.741 | H32: =+Tabla551857211411[[#This Row],[COSTO]]/Tabla551857211411[[#This Row],[BASE]] -> 1.3978343 | I32: =+Tabla551857211411[[#This Row],[BASE]]/Tabla551857211411[[#This Row],[COSTO]] -> 0.7153924 | J32: =+VLOOKUP(Tabla551857211411[[#This Row],[ADICIONES]],Tabla77[#All],3,0) -> 1 | K32: =+D32/(100-70)*100 -> 73343.156 | L32: =+K32/1.08*0.08 -> 5432.8263 | M32: =+Tabla551857211411[[#This Row],[PRECIO SUGERIDO]]+Tabla551857211411[[#This Row],[ICO2]] -> 78775.982 | O32: =+N32/1.08*0.08 -> 0 | P32: =+Tabla551857211411[[#This Row],[PRECIO N]]-Tabla551857211411[[#This Row],[ICO 8%2]] -> 0 | Q32: =+Tabla551857211411[[#This Row],[COSTO]]/Tabla551857211411[[#This Row],[CARTA]] -> #DIV/0! | R32: =+Tabla551857211411[[#This Row],[PRECIO N]]/Tabla551857211411[[#This Row],[COSTO]] -> 0
A33: 27 | B33: =+ADICIONES!A328 -> QUESO PARMESSANO | D33: =+ADICIONES!J331 -> 1280.7375 | E33: =+ADICIONES!J332 -> 8000 | F33: =+E33/1.08*0.08 -> 592.59259 | G33: =+Tabla551857211411[[#This Row],[VENTA]]-Tabla551857211411[[#This Row],[ICO 8%]] -> 7407.4074 | H33: =+Tabla551857211411[[#This Row],[COSTO]]/Tabla551857211411[[#This Row],[BASE]] -> 0.17289956 | I33: =+Tabla551857211411[[#This Row],[BASE]]/Tabla551857211411[[#This Row],[COSTO]] -> 5.7837046 | J33: =+VLOOKUP(Tabla551857211411[[#This Row],[ADICIONES]],Tabla77[#All],3,0) -> 10 | K33: =+D33/(100-70)*100 -> 4269.125 | L33: =+K33/1.08*0.08 -> 316.23148 | M33: =+Tabla551857211411[[#This Row],[PRECIO SUGERIDO]]+Tabla551857211411[[#This Row],[ICO2]] -> 4585.3565 | O33: =+N33/1.08*0.08 -> 0 | P33: =+Tabla551857211411[[#This Row],[PRECIO N]]-Tabla551857211411[[#This Row],[ICO 8%2]] -> 0 | Q33: =+Tabla551857211411[[#This Row],[COSTO]]/Tabla551857211411[[#This Row],[CARTA]] -> #DIV/0! | R33: =+Tabla551857211411[[#This Row],[PRECIO N]]/Tabla551857211411[[#This Row],[COSTO]] -> 0
A34: 28 | B34: =+ADICIONES!A341 -> SALSA A LA HUANCAINA | D34: =+ADICIONES!J344 -> 385.97473 | E34: =+ADICIONES!J345 -> 2900 | F34: =+E34/1.08*0.08 -> 214.81481 | G34: =+Tabla551857211411[[#This Row],[VENTA]]-Tabla551857211411[[#This Row],[ICO 8%]] -> 2685.1852 | H34: =+Tabla551857211411[[#This Row],[COSTO]]/Tabla551857211411[[#This Row],[BASE]] -> 0.14374231 | I34: =+Tabla551857211411[[#This Row],[BASE]]/Tabla551857211411[[#This Row],[COSTO]] -> 6.9568938 | J34: =+VLOOKUP(Tabla551857211411[[#This Row],[ADICIONES]],Tabla77[#All],3,0) -> 25 | K34: =+D34/(100-70)*100 -> 1286.5824 | L34: =+K34/1.08*0.08 -> 95.302402 | M34: =+Tabla551857211411[[#This Row],[PRECIO SUGERIDO]]+Tabla551857211411[[#This Row],[ICO2]] -> 1381.8848 | O34: =+N34/1.08*0.08 -> 0 | P34: =+Tabla551857211411[[#This Row],[PRECIO N]]-Tabla551857211411[[#This Row],[ICO 8%2]] -> 0 | Q34: =+Tabla551857211411[[#This Row],[COSTO]]/Tabla551857211411[[#This Row],[CARTA]] -> #DIV/0! | R34: =+Tabla551857211411[[#This Row],[PRECIO N]]/Tabla551857211411[[#This Row],[COSTO]] -> 0
A35: 29 | B35: =+ADICIONES!A354 -> SALSA CRIOLLA | D35: =+ADICIONES!J357 -> #N/A | E35: =+ADICIONES!J358 -> 2900 | F35: =+E35/1.08*0.08 -> 214.81481 | G35: =+Tabla551857211411[[#This Row],[VENTA]]-Tabla551857211411[[#This Row],[ICO 8%]] -> 2685.1852 | H35: =+Tabla551857211411[[#This Row],[COSTO]]/Tabla551857211411[[#This Row],[BASE]] -> #N/A | I35: =+Tabla551857211411[[#This Row],[BASE]]/Tabla551857211411[[#This Row],[COSTO]] -> #N/A | J35: =+VLOOKUP(Tabla551857211411[[#This Row],[ADICIONES]],Tabla77[#All],3,0) -> 13 | K35: =+D35/(100-70)*100 -> #N/A | L35: =+K35/1.08*0.08 -> #N/A | M35: =+Tabla551857211411[[#This Row],[PRECIO SUGERIDO]]+Tabla551857211411[[#This Row],[ICO2]] -> #N/A | O35: =+N35/1.08*0.08 -> 0 | P35: =+Tabla551857211411[[#This Row],[PRECIO N]]-Tabla551857211411[[#This Row],[ICO 8%2]] -> 0 | Q35: =+Tabla551857211411[[#This Row],[COSTO]]/Tabla551857211411[[#This Row],[CARTA]] -> #N/A | R35: =+Tabla551857211411[[#This Row],[PRECIO N]]/Tabla551857211411[[#This Row],[COSTO]] -> #N/A
A36: 30 | B36: =+ADICIONES!A367 -> SALSA DE TOMATE | D36: =+ADICIONES!J370 -> 593.09069 | E36: =+ADICIONES!J371 -> 3900 | F36: =+E36/1.08*0.08 -> 288.88889 | G36: =+Tabla551857211411[[#This Row],[VENTA]]-Tabla551857211411[[#This Row],[ICO 8%]] -> 3611.1111 | H36: =+Tabla551857211411[[#This Row],[COSTO]]/Tabla551857211411[[#This Row],[BASE]] -> 0.1642405 | I36: =+Tabla551857211411[[#This Row],[BASE]]/Tabla551857211411[[#This Row],[COSTO]] -> 6.0886323 | J36: =+VLOOKUP(Tabla551857211411[[#This Row],[ADICIONES]],Tabla77[#All],3,0) -> #N/A | K36: =+D36/(100-70)*100 -> 1976.969 | L36: =+K36/1.08*0.08 -> 146.44215 | M36: =+Tabla551857211411[[#This Row],[PRECIO SUGERIDO]]+Tabla551857211411[[#This Row],[ICO2]] -> 2123.4111 | O36: =+N36/1.08*0.08 -> 0 | P36: =+Tabla551857211411[[#This Row],[PRECIO N]]-Tabla551857211411[[#This Row],[ICO 8%2]] -> 0 | Q36: =+Tabla551857211411[[#This Row],[COSTO]]/Tabla551857211411[[#This Row],[CARTA]] -> #DIV/0! | R36: =+Tabla551857211411[[#This Row],[PRECIO N]]/Tabla551857211411[[#This Row],[COSTO]] -> 0
A37: 31 | B37: =+ADICIONES!A380 -> SALSA EMPANADAS | D37: =+ADICIONES!J383 -> 724.48306 | E37: =+ADICIONES!J384 -> 3900 | F37: =+E37/1.08*0.08 -> 288.88889 | G37: =+Tabla551857211411[[#This Row],[VENTA]]-Tabla551857211411[[#This Row],[ICO 8%]] -> 3611.1111 | H37: =+Tabla551857211411[[#This Row],[COSTO]]/Tabla551857211411[[#This Row],[BASE]] -> 0.20062608 | I37: =+Tabla551857211411[[#This Row],[BASE]]/Tabla551857211411[[#This Row],[COSTO]] -> 4.9843969 | J37: =+VLOOKUP(Tabla551857211411[[#This Row],[ADICIONES]],Tabla77[#All],3,0) -> 1 | K37: =+D37/(100-70)*100 -> 2414.9435 | L37: =+K37/1.08*0.08 -> 178.88471 | M37: =+Tabla551857211411[[#This Row],[PRECIO SUGERIDO]]+Tabla551857211411[[#This Row],[ICO2]] -> 2593.8282 | O37: =+N37/1.08*0.08 -> 0 | P37: =+Tabla551857211411[[#This Row],[PRECIO N]]-Tabla551857211411[[#This Row],[ICO 8%2]] -> 0 | Q37: =+Tabla551857211411[[#This Row],[COSTO]]/Tabla551857211411[[#This Row],[CARTA]] -> #DIV/0! | R37: =+Tabla551857211411[[#This Row],[PRECIO N]]/Tabla551857211411[[#This Row],[COSTO]] -> 0
A38: 32 | B38: =+ADICIONES!A393 -> SALSA HUACAINA | D38: =+ADICIONES!J396 -> 385.97473 | E38: =+ADICIONES!J397 -> 3900 | F38: =+E38/1.08*0.08 -> 288.88889 | G38: =+Tabla551857211411[[#This Row],[VENTA]]-Tabla551857211411[[#This Row],[ICO 8%]] -> 3611.1111 | H38: =+Tabla551857211411[[#This Row],[COSTO]]/Tabla551857211411[[#This Row],[BASE]] -> 0.10688531 | I38: =+Tabla551857211411[[#This Row],[BASE]]/Tabla551857211411[[#This Row],[COSTO]] -> 9.3558227 | J38: =+VLOOKUP(Tabla551857211411[[#This Row],[ADICIONES]],Tabla77[#All],3,0) -> 7 | K38: =+D38/(100-70)*100 -> 1286.5824 | L38: =+K38/1.08*0.08 -> 95.302402 | M38: =+Tabla551857211411[[#This Row],[PRECIO SUGERIDO]]+Tabla551857211411[[#This Row],[ICO2]] -> 1381.8848 | O38: =+N38/1.08*0.08 -> 0 | P38: =+Tabla551857211411[[#This Row],[PRECIO N]]-Tabla551857211411[[#This Row],[ICO 8%2]] -> 0 | Q38: =+Tabla551857211411[[#This Row],[COSTO]]/Tabla551857211411[[#This Row],[CARTA]] -> #DIV/0! | R38: =+Tabla551857211411[[#This Row],[PRECIO N]]/Tabla551857211411[[#This Row],[COSTO]] -> 0
A39: 33 | B39: =+ADICIONES!A405 -> SALSA MELCOCHA | D39: =+ADICIONES!J408 -> 2990.1656 | E39: =+ADICIONES!J409 -> 3900 | F39: =+E39/1.08*0.08 -> 288.88889 | G39: =+Tabla551857211411[[#This Row],[VENTA]]-Tabla551857211411[[#This Row],[ICO 8%]] -> 3611.1111 | H39: =+Tabla551857211411[[#This Row],[COSTO]]/Tabla551857211411[[#This Row],[BASE]] -> 0.82804587 | I39: =+Tabla551857211411[[#This Row],[BASE]]/Tabla551857211411[[#This Row],[COSTO]] -> 1.2076626 | J39: =+VLOOKUP(Tabla551857211411[[#This Row],[ADICIONES]],Tabla77[#All],3,0) -> 3 | K39: =+D39/(100-70)*100 -> 9967.2188 | L39: =+K39/1.08*0.08 -> 738.3125 | M39: =+Tabla551857211411[[#This Row],[PRECIO SUGERIDO]]+Tabla551857211411[[#This Row],[ICO2]] -> 10705.531 | O39: =+N39/1.08*0.08 -> 0 | P39: =+Tabla551857211411[[#This Row],[PRECIO N]]-Tabla551857211411[[#This Row],[ICO 8%2]] -> 0 | Q39: =+Tabla551857211411[[#This Row],[COSTO]]/Tabla551857211411[[#This Row],[CARTA]] -> #DIV/0! | R39: =+Tabla551857211411[[#This Row],[PRECIO N]]/Tabla551857211411[[#This Row],[COSTO]] -> 0
A40: 34 | B40: =+ADICIONES!A419 -> SALSA TERIYAKI | D40: =+ADICIONES!J422 -> 326.57 | E40: =+ADICIONES!J423 -> 4900 | F40: =+E40/1.08*0.08 -> 362.96296 | G40: =+Tabla551857211411[[#This Row],[VENTA]]-Tabla551857211411[[#This Row],[ICO 8%]] -> 4537.037 | H40: =+Tabla551857211411[[#This Row],[COSTO]]/Tabla551857211411[[#This Row],[BASE]] -> 0.071978694 | I40: =+Tabla551857211411[[#This Row],[BASE]]/Tabla551857211411[[#This Row],[COSTO]] -> 13.893 | J40: =+VLOOKUP(Tabla551857211411[[#This Row],[ADICIONES]],Tabla77[#All],3,0) -> 4 | K40: =+D40/(100-70)*100 -> 1088.5667 | L40: =+K40/1.08*0.08 -> 80.634568 | M40: =+Tabla551857211411[[#This Row],[PRECIO SUGERIDO]]+Tabla551857211411[[#This Row],[ICO2]] -> 1169.2012 | O40: =+N40/1.08*0.08 -> 0 | P40: =+Tabla551857211411[[#This Row],[PRECIO N]]-Tabla551857211411[[#This Row],[ICO 8%2]] -> 0 | Q40: =+Tabla551857211411[[#This Row],[COSTO]]/Tabla551857211411[[#This Row],[CARTA]] -> #DIV/0! | R40: =+Tabla551857211411[[#This Row],[PRECIO N]]/Tabla551857211411[[#This Row],[COSTO]] -> 0
A41: 35 | B41: =+ADICIONES!A431 -> SALSA WONTON | D41: =+ADICIONES!J434 -> 488.62371 | E41: =+ADICIONES!J435 -> 2900 | F41: =+E41/1.08*0.08 -> 214.81481 | G41: =+Tabla551857211411[[#This Row],[VENTA]]-Tabla551857211411[[#This Row],[ICO 8%]] -> 2685.1852 | H41: =+Tabla551857211411[[#This Row],[COSTO]]/Tabla551857211411[[#This Row],[BASE]] -> 0.18197021 | I41: =+Tabla551857211411[[#This Row],[BASE]]/Tabla551857211411[[#This Row],[COSTO]] -> 5.4954051 | J41: =+VLOOKUP(Tabla551857211411[[#This Row],[ADICIONES]],Tabla77[#All],3,0) -> #N/A | K41: =+D41/(100-70)*100 -> 1628.7457 | L41: =+K41/1.08*0.08 -> 120.64783 | M41: =+Tabla551857211411[[#This Row],[PRECIO SUGERIDO]]+Tabla551857211411[[#This Row],[ICO2]] -> 1749.3935 | O41: =+N41/1.08*0.08 -> 0 | P41: =+Tabla551857211411[[#This Row],[PRECIO N]]-Tabla551857211411[[#This Row],[ICO 8%2]] -> 0 | Q41: =+Tabla551857211411[[#This Row],[COSTO]]/Tabla551857211411[[#This Row],[CARTA]] -> #DIV/0! | R41: =+Tabla551857211411[[#This Row],[PRECIO N]]/Tabla551857211411[[#This Row],[COSTO]] -> 0
A42: 36 | B42: =+ADICIONES!A445 -> SHOT LECHE DE TIGRE | D42: =+ADICIONES!J448 -> 320.6541 | E42: =+ADICIONES!J449 -> 5000 | F42: =+E42/1.08*0.08 -> 370.37037 | G42: =+Tabla551857211411[[#This Row],[VENTA]]-Tabla551857211411[[#This Row],[ICO 8%]] -> 4629.6296 | H42: =+Tabla551857211411[[#This Row],[COSTO]]/Tabla551857211411[[#This Row],[BASE]] -> 0.069261287 | I42: =+Tabla551857211411[[#This Row],[BASE]]/Tabla551857211411[[#This Row],[COSTO]] -> 14.43808 | J42: =+VLOOKUP(Tabla551857211411[[#This Row],[ADICIONES]],Tabla77[#All],3,0) -> 7 | K42: =+D42/(100-70)*100 -> 1068.847 | L42: =+K42/1.08*0.08 -> 79.173853 | M42: =+Tabla551857211411[[#This Row],[PRECIO SUGERIDO]]+Tabla551857211411[[#This Row],[ICO2]] -> 1148.0209 | O42: =+N42/1.08*0.08 -> 0 | P42: =+Tabla551857211411[[#This Row],[PRECIO N]]-Tabla551857211411[[#This Row],[ICO 8%2]] -> 0 | Q42: =+Tabla551857211411[[#This Row],[COSTO]]/Tabla551857211411[[#This Row],[CARTA]] -> #DIV/0! | R42: =+Tabla551857211411[[#This Row],[PRECIO N]]/Tabla551857211411[[#This Row],[COSTO]] -> 0
A43: 37 | B43: =+ADICIONES!A457 -> SOLOMITO ROCOTO | D43: =+ADICIONES!J460 -> 12894 | E43: =+ADICIONES!J461 -> 11500 | F43: =+E43/1.08*0.08 -> 851.85185 | G43: =+Tabla551857211411[[#This Row],[VENTA]]-Tabla551857211411[[#This Row],[ICO 8%]] -> 10648.148 | H43: =+Tabla551857211411[[#This Row],[COSTO]]/Tabla551857211411[[#This Row],[BASE]] -> 1.2109148 | I43: =+Tabla551857211411[[#This Row],[BASE]]/Tabla551857211411[[#This Row],[COSTO]] -> 0.82582194 | J43: =+VLOOKUP(Tabla551857211411[[#This Row],[ADICIONES]],Tabla77[#All],3,0) -> 5 | K43: =+D43/(100-70)*100 -> 42980 | L43: =+K43/1.08*0.08 -> 3183.7037 | M43: =+Tabla551857211411[[#This Row],[PRECIO SUGERIDO]]+Tabla551857211411[[#This Row],[ICO2]] -> 46163.704 | O43: =+N43/1.08*0.08 -> 0 | P43: =+Tabla551857211411[[#This Row],[PRECIO N]]-Tabla551857211411[[#This Row],[ICO 8%2]] -> 0 | Q43: =+Tabla551857211411[[#This Row],[COSTO]]/Tabla551857211411[[#This Row],[CARTA]] -> #DIV/0! | R43: =+Tabla551857211411[[#This Row],[PRECIO N]]/Tabla551857211411[[#This Row],[COSTO]] -> 0
A44: 38 | B44: =+ADICIONES!A468 -> TUBOS DE CALAMAR | D44: =+ADICIONES!J471 -> 4202.1401 | E44: =+ADICIONES!J472 -> 15000 | F44: =+E44/1.08*0.08 -> 1111.1111 | G44: =+Tabla551857211411[[#This Row],[VENTA]]-Tabla551857211411[[#This Row],[ICO 8%]] -> 13888.889 | H44: =+Tabla551857211411[[#This Row],[COSTO]]/Tabla551857211411[[#This Row],[BASE]] -> 0.30255409 | I44: =+Tabla551857211411[[#This Row],[BASE]]/Tabla551857211411[[#This Row],[COSTO]] -> 3.3051941 | J44: =+VLOOKUP(Tabla551857211411[[#This Row],[ADICIONES]],Tabla77[#All],3,0) -> 3 | K44: =+D44/(100-70)*100 -> 14007.134 | L44: =+K44/1.08*0.08 -> 1037.5655 | M44: =+Tabla551857211411[[#This Row],[PRECIO SUGERIDO]]+Tabla551857211411[[#This Row],[ICO2]] -> 15044.699 | O44: =+N44/1.08*0.08 -> 0 | P44: =+Tabla551857211411[[#This Row],[PRECIO N]]-Tabla551857211411[[#This Row],[ICO 8%2]] -> 0 | Q44: =+Tabla551857211411[[#This Row],[COSTO]]/Tabla551857211411[[#This Row],[CARTA]] -> #DIV/0! | R44: =+Tabla551857211411[[#This Row],[PRECIO N]]/Tabla551857211411[[#This Row],[COSTO]] -> 0
...

Sheet MEDELLIN GOURMET
B3: Entradas | D3: 1
B4: =+'MATRIZ CARTA'!B58 -> SPRING ROLLS AJÃ DE GALLINA | C4: =+'MATRIZ CARTA'!D58 -> 10080.636 | D4: 35000 | F4: =+C6*D3 -> 7822.0197 | K4: 35000 | L4: =+K4*1 -> 35000
B5: =+'MATRIZ CARTA'!B79 -> CEVICHE DE CHAMPIÑON | C5: =+'MATRIZ CARTA'!D79 -> 9003.4438
B6: =+'MATRIZ CARTA'!B92 -> CAUSA DE SALMON ACEVICHADA | C6: =+'MATRIZ CARTA'!D92 -> 7822.0197
B8: Fuertes | D8: 2
B9: =+'MATRIZ CARTA'!B110 -> ARROZ DE CHANCHO | C9: =+'MATRIZ CARTA'!D110 -> 17927.628
B10: =+'MATRIZ CARTA'!B124 -> LOMO ANTICUCHERO | C10: =+'MATRIZ CARTA'!D124 -> 22470.295 | D10: 67900 | F10: =+C9+C10 -> 40397.922 | K10: 67900 | L10: =+K10*2 -> 135800
B11: =+'MATRIZ CARTA'!B77 -> MIXTO TRADICIONAL | C11: =+'MATRIZ CARTA'!D77 -> 15690.988
B13: Postre | D13: 1 | F13: =+C15*D13 -> 2983.0285
B14: =+'MATRIZ CARTA'!B140 -> SPRING ROLLS DE NUTELLA | C14: =+'MATRIZ CARTA'!D140 -> 7851.0826
B15: =+'MATRIZ CARTA'!B141 -> SUSPIRO ROCOTO | C15: =+'MATRIZ CARTA'!D141 -> 2983.0285
B16: =+'MATRIZ CARTA'!B142 -> TORTA DE CHOCOLATE | C16: =+'MATRIZ CARTA'!D142 -> 9655.6686 | D16: 27000 | K16: 27000 | L16: =+K16*1 -> 27000
B18: Bebidas | H18: ANALISIS RECETA
B19: Te Hatsu | C19: 3334 | D19: 1 | E19: 15000 | F19: =+D19*C19 -> 3334 | H19: COSTO DEL PLATO | I19: =+F24 -> 61777.971 | K19: 15000 | L19: =+K19*2 -> 30000
B20: Cerveza | C20: 3333 | D20: 2 | E20: 15000 | F20: =+D20*C20 -> 6666 | H20: MARGEN DE ERROR DEL 5% | K20: 15000 | L20: =+K20*1 -> 15000
B21: Café | C21: 575 | D21: 1 | E21: 6000 | F21: =+D21*C21 -> 575 | H21: COSTO + MARGEN ERROR | I21: =+F24 -> 61777.971 | K21: 6000 | L21: =+K21*1 -> 6000
H22: VALOR DE VENTA | I22: 159000
H23: IPOCONSUMO | I23: =+I22/1.08*0.08 -> 11777.778
F24: =+F4+F10+F13+F19+F20+F21 -> 61777.971 | H24: VALOR ANTES DE IPO | I24: =+I22-I23 -> 147222.22 | L24: =SUM(L4:L22) -> 248800
H25: MARGEN. | I25: =+I21/I24 -> 0.41962395
H26: GANANCIA | I26: =+I24-I21 -> 85444.252 | L26: =+L24*35% -> 87080
H27: MARGEN PORCENTUAL | I27: =+I26/I21 -> 1.3830861

Sheet CAUSAS
B7: CAUSA LIMEÃ‘A | J7: ANALISIS RECETA
B8: Ingrediente | C8: Und | D8: Unidades Netas | E8: % Merma | F8: Unidades | G8: Costo | H8: Total costo | J8: COSTO DEL PLATO | K8: =+H9+3851 -> 4784.338
B9: AGUACATE CHOCKETTE X KILO | C9: g | D9: 50 | E9: 25 | F9: 66.667 | G9: =+VLOOKUP(Tabla1103453454455456479108131138145424430432[[#This Row],[Ingrediente]],Tabla34[#All],3,0) -> 14 | H9: =+Tabla1103453454455456479108131138145424430432[[#This Row],[Costo]]*Tabla1103453454455456479108131138145424430432[[#This Row],[Unidades]] -> 933.338 | J9: MARGEN DE ERROR DEL 5% | K9: =+K8*5% -> 239.2169
B10: CILANTRO LIMPIO X KILO | C10: g | D10: 1 | E10: 40 | F10: 1.667 | G10: =+VLOOKUP(Tabla1103453454455456479108131138145424430432[[#This Row],[Ingrediente]],Tabla34[#All],3,0) -> 5.5 | H10: =+Tabla1103453454455456479108131138145424430432[[#This Row],[Costo]]*Tabla1103453454455456479108131138145424430432[[#This Row],[Unidades]] -> 9.1685 | J10: COSTO + MARGEN ERROR | K10: =+K8+K9 -> 5023.5549
B11: HUEVO DE CODORNIZ *24UND | C11: uds | D11: 1 | E11: 0 | F11: 1 | G11: =+VLOOKUP(Tabla1103453454455456479108131138145424430432[[#This Row],[Ingrediente]],Tabla34[#All],3,0) -> 354.16667 | H11: =+Tabla1103453454455456479108131138145424430432[[#This Row],[Costo]]*Tabla1103453454455456479108131138145424430432[[#This Row],[Unidades]] -> 354.16667 | J11: VALOR DE VENTA | K11: 37000
B12: SUB. CAUSA AJI AMARILLO | C12: g | D12: 80 | E12: 0 | F12: 80 | G12: =+VLOOKUP(Tabla1103453454455456479108131138145424430432[[#This Row],[Ingrediente]],Tabla34[#All],3,0) -> 1.2544167 | H12: =+Tabla1103453454455456479108131138145424430432[[#This Row],[Costo]]*Tabla1103453454455456479108131138145424430432[[#This Row],[Unidades]] -> 100.35333 | J12: IPOCONSUMO | K12: =+K11/1.08*0.08 -> 2740.7407
B13: SUB. HUANCAINA | C13: g | D13: 15 | E13: 0 | F13: 15 | G13: =+VLOOKUP(Tabla1103453454455456479108131138145424430432[[#This Row],[Ingrediente]],Tabla34[#All],3,0) -> 12.253166 | H13: =+Tabla1103453454455456479108131138145424430432[[#This Row],[Costo]]*Tabla1103453454455456479108131138145424430432[[#This Row],[Unidades]] -> 183.79749 | J13: VALOR ANTES DE IPO | K13: =+K11-K12 -> 34259.259
B14: SUB. MAYONESA ACEVICHADA | C14: g | D14: 10 | E14: 0 | F14: 10 | G14: =+VLOOKUP(Tabla1103453454455456479108131138145424430432[[#This Row],[Ingrediente]],Tabla34[#All],3,0) -> 22.545489 | H14: =+Tabla1103453454455456479108131138145424430432[[#This Row],[Costo]]*Tabla1103453454455456479108131138145424430432[[#This Row],[Unidades]] -> 225.45489 | J14: MARGEN. | K14: =+K10/K13 -> 0.14663349
B15: SUB. POLLO LIMEÃ‘O | C15: uds | D15: 1 | E15: 0 | F15: 1 | G15: =+VLOOKUP(Tabla1103453454455456479108131138145424430432[[#This Row],[Ingrediente]],Tabla34[#All],3,0) -> 1563.6235 | H15: =+Tabla1103453454455456479108131138145424430432[[#This Row],[Costo]]*Tabla1103453454455456479108131138145424430432[[#This Row],[Unidades]] -> 1563.6235 | J15: GANANCIA | K15: =+K13-K10 -> 29235.704
B16: TOGARASHI HACHI 300 GR | C16: g | D16: 1 | E16: 0 | F16: 1 | G16: =+VLOOKUP(Tabla1103453454455456479108131138145424430432[[#This Row],[Ingrediente]],Tabla34[#All],3,0) -> 99.166667 | H16: =+Tabla1103453454455456479108131138145424430432[[#This Row],[Costo]]*Tabla1103453454455456479108131138145424430432[[#This Row],[Unidades]] -> 99.166667 | J16: MARGEN PORCENTUAL | K16: =+K15/K10 -> 5.8197243
B17: TOMATE CHERRY X KILO | C17: g | D17: 20 | E17: 10 | F17: 22.222 | G17: =+VLOOKUP(Tabla1103453454455456479108131138145424430432[[#This Row],[Ingrediente]],Tabla34[#All],3,0) -> 5 | H17: =+Tabla1103453454455456479108131138145424430432[[#This Row],[Costo]]*Tabla1103453454455456479108131138145424430432[[#This Row],[Unidades]] -> 111.11
H18: =SUBTOTAL(109,Tabla1103453454455456479108131138145424430432[Total costo]) -> 3580.179
B20: CAUSA DE ATUN | J20: ANALISIS RECETA
B21: Ingrediente | C21: Und | D21: Unidades Netas | E21: % Merma | F21: Unidades | G21: Costo | H21: Total costo | J21: COSTO DEL PLATO | K21: =+H22+3851 -> 4014.0742
B22: SUB. CAUSA AJI AMARILLO | C22: g | D22: 130 | E22: 0 | F22: 130 | G22: =+VLOOKUP(Tabla110345345445545647910813113814542443043241[[#This Row],[Ingrediente]],Tabla34[#All],3,0) -> 1.2544167 | H22: =+Tabla110345345445545647910813113814542443043241[[#This Row],[Costo]]*Tabla110345345445545647910813113814542443043241[[#This Row],[Unidades]] -> 163.07416 | J22: MARGEN DE ERROR DEL 5% | K22: =+K21*5% -> 200.70371
B23: AGUACATE CHOCKETTE X KILO | C23: g | D23: 60 | E23: 25 | F23: 80 | G23: =+VLOOKUP(Tabla110345345445545647910813113814542443043241[[#This Row],[Ingrediente]],Tabla34[#All],3,0) -> 14 | H23: =+Tabla110345345445545647910813113814542443043241[[#This Row],[Costo]]*Tabla110345345445545647910813113814542443043241[[#This Row],[Unidades]] -> 1120 | J23: COSTO + MARGEN ERROR | K23: =+K21+K22 -> 4214.7779
B24: SUB. CAUSA DE ATUN | C24: g | D24: 100 | E24: 0 | F24: 100 | G24: =+VLOOKUP(Tabla110345345445545647910813113814542443043241[[#This Row],[Ingrediente]],Tabla34[#All],3,0) -> 32.346781 | H24: =+Tabla110345345445545647910813113814542443043241[[#This Row],[Costo]]*Tabla110345345445545647910813113814542443043241[[#This Row],[Unidades]] -> 3234.6781 | J24: VALOR DE VENTA | K24: 37000
B25: FLORES COMESTIBLES (PENSAMIENTOS) | C25: g | D25: 1 | E25: 0 | F25: 1 | G25: =+VLOOKUP(Tabla110345345445545647910813113814542443043241[[#This Row],[Ingrediente]],Tabla34[#All],3,0) -> 180 | H25: =+Tabla110345345445545647910813113814542443043241[[#This Row],[Costo]]*Tabla110345345445545647910813113814542443043241[[#This Row],[Unidades]] -> 180 | J25: IPOCONSUMO | K25: =+K24/1.08*0.08 -> 2740.7407
B26: TOGARASHI HACHI 300 GR | C26: g | D26: 1 | E26: 0 | F26: 1 | G26: =+VLOOKUP(Tabla110345345445545647910813113814542443043241[[#This Row],[Ingrediente]],Tabla34[#All],3,0) -> 99.166667 | H26: =+Tabla110345345445545647910813113814542443043241[[#This Row],[Costo]]*Tabla110345345445545647910813113814542443043241[[#This Row],[Unidades]] -> 99.166667 | J26: VALOR ANTES DE IPO | K26: =+K24-K25 -> 34259.259
B27: CILANTRO LIMPIO X KILO | C27: g | D27: 1 | E27: 40 | F27: 1.667 | G27: =+VLOOKUP(Tabla110345345445545647910813113814542443043241[[#This Row],[Ingrediente]],Tabla34[#All],3,0) -> 5.5 | H27: =+Tabla110345345445545647910813113814542443043241[[#This Row],[Costo]]*Tabla110345345445545647910813113814542443043241[[#This Row],[Unidades]] -> 9.1685 | J27: MARGEN. | K27: =+K23/K26 -> 0.12302595
B28: SUB. BASE DE MAYO ACEVICHADA (ROCOTO) | C28: g | D28: 20 | E28: 0 | F28: 20 | G28: =+VLOOKUP(Tabla110345345445545647910813113814542443043241[[#This Row],[Ingrediente]],Tabla34[#All],3,0) -> 19.796649 | H28: =+Tabla110345345445545647910813113814542443043241[[#This Row],[Costo]]*Tabla110345345445545647910813113814542443043241[[#This Row],[Unidades]] -> 395.93298 | J28: GANANCIA | K28: =+K26-K23 -> 30044.481
H29: =SUBTOTAL(109,Tabla110345345445545647910813113814542443043241[Total costo]) -> 5202.0204 | J29: MARGEN PORCENTUAL | K29: =+K28/K23 -> 7.1283665
B35: CAUSA DE CAMARONES | J35: ANALISIS RECETA
B36: Ingrediente | C36: Und | D36: Unidades Netas | E36: % Merma | F36: Unidades | G36: Costo | H36: Total costo | J36: COSTO DEL PLATO | K36: =+H37+3851 -> 8708.1429
B37: CAMARON CRUDO 41-50 0% PORCIONX 7UND PAQUETE POR 10 PORCIONES | C37: uds | D37: 10 | E37: 0 | F37: 10 | G37: =+VLOOKUP(Tabla11034534544554564791081311381454244304324179[[#This Row],[Ingrediente]],Tabla34[#All],3,0) -> 485.71429 | H37: =+Tabla11034534544554564791081311381454244304324179[[#This Row],[Costo]]*Tabla11034534544554564791081311381454244304324179[[#This Row],[Unidades]] -> 4857.1429 | J37: MARGEN DE ERROR DEL 5% | K37: =+K36*5% -> 435.40714
B38: CILANTRO LIMPIO X KILO | C38: g | D38: 5 | E38: 40 | F38: 8.333 | G38: =+VLOOKUP(Tabla11034534544554564791081311381454244304324179[[#This Row],[Ingrediente]],Tabla34[#All],3,0) -> 5.5 | H38: =+Tabla11034534544554564791081311381454244304324179[[#This Row],[Costo]]*Tabla11034534544554564791081311381454244304324179[[#This Row],[Unidades]] -> 45.8315 | J38: COSTO + MARGEN ERROR | K38: =+K36+K37 -> 9143.55
B39: HUEVO DE CODORNIZ *24UND | C39: uds | D39: 1.5 | E39: 0 | F39: 1.5 | G39: =+VLOOKUP(Tabla11034534544554564791081311381454244304324179[[#This Row],[Ingrediente]],Tabla34[#All],3,0) -> 354.16667 | H39: =+Tabla11034534544554564791081311381454244304324179[[#This Row],[Costo]]*Tabla11034534544554564791081311381454244304324179[[#This Row],[Unidades]] -> 531.25 | J39: VALOR DE VENTA | K39: 37000
B40: SUB. CAUSA AJI AMARILLO | C40: g | D40: 130 | E40: 0 | F40: 130 | G40: =+VLOOKUP(Tabla11034534544554564791081311381454244304324179[[#This Row],[Ingrediente]],Tabla34[#All],3,0) -> 1.2544167 | H40: =+Tabla11034534544554564791081311381454244304324179[[#This Row],[Costo]]*Tabla11034534544554564791081311381454244304324179[[#This Row],[Unidades]] -> 163.07416 | J40: IPOCONSUMO | K40: =+K39/1.08*0.08 -> 2740.7407
B41: SUB. CHALACA | C41: g | D41: 25 | E41: 0 | F41: 25 | G41: =+VLOOKUP(Tabla11034534544554564791081311381454244304324179[[#This Row],[Ingrediente]],Tabla34[#All],3,0) -> 11.132676 | H41: =+Tabla11034534544554564791081311381454244304324179[[#This Row],[Costo]]*Tabla11034534544554564791081311381454244304324179[[#This Row],[Unidades]] -> 278.31689 | J41: VALOR ANTES DE IPO | K41: =+K39-K40 -> 34259.259
B42: SUB. GUACAMOLE (ROCOTO) | C42: g | D42: 10 | E42: 0 | F42: 10 | G42: =+VLOOKUP(Tabla11034534544554564791081311381454244304324179[[#This Row],[Ingrediente]],Tabla34[#All],3,0) -> 24.804271 | H42: =+Tabla11034534544554564791081311381454244304324179[[#This Row],[Costo]]*Tabla11034534544554564791081311381454244304324179[[#This Row],[Unidades]] -> 248.04271 | J42: MARGEN. | K42: =+K38/K41 -> 0.26689281
B43: SUB. MAYONESA ACEVICHADA | C43: g | D43: 20 | E43: 0 | F43: 20 | G43: =+VLOOKUP(Tabla11034534544554564791081311381454244304324179[[#This Row],[Ingrediente]],Tabla34[#All],3,0) -> 22.545489 | H43: =+Tabla11034534544554564791081311381454244304324179[[#This Row],[Costo]]*Tabla11034534544554564791081311381454244304324179[[#This Row],[Unidades]] -> 450.90977 | J43: GANANCIA | K43: =+K41-K38 -> 25115.709
B44: SUB. QUINUA POP | C44: g | D44: 5 | E44: 0 | F44: 5 | G44: =+VLOOKUP(Tabla11034534544554564791081311381454244304324179[[#This Row],[Ingrediente]],Tabla34[#All],3,0) -> 5.9757462 | H44: =+Tabla11034534544554564791081311381454244304324179[[#This Row],[Costo]]*Tabla11034534544554564791081311381454244304324179[[#This Row],[Unidades]] -> 29.878731 | J44: MARGEN PORCENTUAL | K44: =+K43/K38 -> 2.7468225
B45: SUB. SALSA GOLF | C45: g | D45: 60 | E45: 0 | F45: 60 | G45: =+VLOOKUP(Tabla11034534544554564791081311381454244304324179[[#This Row],[Ingrediente]],Tabla34[#All],3,0) -> 25.084593 | H45: =+Tabla11034534544554564791081311381454244304324179[[#This Row],[Costo]]*Tabla11034534544554564791081311381454244304324179[[#This Row],[Unidades]] -> 1505.0756
B46: TOMATE CHERRY X KILO | C46: g | D46: 20 | E46: 10 | F46: 22.222 | G46: =+VLOOKUP(Tabla11034534544554564791081311381454244304324179[[#This Row],[Ingrediente]],Tabla34[#All],3,0) -> 5 | H46: =+Tabla11034534544554564791081311381454244304324179[[#This Row],[Costo]]*Tabla11034534544554564791081311381454244304324179[[#This Row],[Unidades]] -> 111.11
H47: =SUBTOTAL(109,Tabla11034534544554564791081311381454244304324179[Total costo]) -> 8220.6322
B49: CAUSA ACEVICHADA | J49: ANALISIS RECETA
B50: Ingrediente | C50: Und | D50: Unidades Netas | E50: % Merma | F50: Unidades | G50: Costo | H50: Total costo | J50: COSTO DEL PLATO | K50: =+H51+3851 -> 4784.338
B51: AGUACATE CHOCKETTE X KILO | C51: g | D51: 50 | E51: 25 | F51: 66.667 | G51: =+VLOOKUP(Tabla11034534544554564791081311381454244304324179216[[#This Row],[Ingrediente]],Tabla34[#All],3,0) -> 14 | H51: =+Tabla11034534544554564791081311381454244304324179216[[#This Row],[Costo]]*Tabla11034534544554564791081311381454244304324179216[[#This Row],[Unidades]] -> 933.338 | J51: MARGEN DE ERROR DEL 5% | K51: =+K50*5% -> 239.2169
B52: AJI ROCOTO X KILO | C52: g | D52: 5 | E52: 60 | F52: 12.5 | G52: =+VLOOKUP(Tabla11034534544554564791081311381454244304324179216[[#This Row],[Ingrediente]],Tabla34[#All],3,0) -> 14 | H52: =+Tabla11034534544554564791081311381454244304324179216[[#This Row],[Costo]]*Tabla11034534544554564791081311381454244304324179216[[#This Row],[Unidades]] -> 175 | J52: COSTO + MARGEN ERROR | K52: =+K50+K51 -> 5023.5549
B53: CEBOLLA MORADA LIMPIA | C53: g | D53: 20 | E53: 10 | F53: 22.222 | G53: =+VLOOKUP(Tabla11034534544554564791081311381454244304324179216[[#This Row],[Ingrediente]],Tabla34[#All],3,0) -> 3.8 | H53: =+Tabla11034534544554564791081311381454244304324179216[[#This Row],[Costo]]*Tabla11034534544554564791081311381454244304324179216[[#This Row],[Unidades]] -> 84.4436 | J53: VALOR DE VENTA | K53: 37000
...

Sheet CEVICHES
B6: CHEVICHE PARRILLADO | J6: ANALISIS RECETA
B7: Ingrediente | C7: Und | D7: Unidades Netas | E7: % Merma | F7: Unidades | G7: Costo | H7: Total costo | J7: COSTO DEL PLATO | K7: =SUM(Tabla1103453454455456479108135149[Total costo]) -> 23351.12
B8: ACEITE VEGETAL X 20LT | C8: g | D8: 15 | E8: 0 | F8: 15 | G8: =+VLOOKUP(Tabla1103453454455456479108135149[[#This Row],[Ingrediente]],Tabla34[#All],3,0) -> 8.2499667 | H8: =+Tabla1103453454455456479108135149[[#This Row],[Costo]]*Tabla1103453454455456479108135149[[#This Row],[Unidades]] -> 123.7495 | J8: MARGEN DE ERROR DEL 5% | K8: =+K7*5% -> 1167.556
B9: AGUACATE CHOCKETTE X KILO | C9: g | D9: 80 | E9: 25 | F9: 106.667 | G9: =+VLOOKUP(Tabla1103453454455456479108135149[[#This Row],[Ingrediente]],Tabla34[#All],3,0) -> 14 | H9: =+Tabla1103453454455456479108135149[[#This Row],[Costo]]*Tabla1103453454455456479108135149[[#This Row],[Unidades]] -> 1493.338 | J9: COSTO + MARGEN ERROR | K9: =+K7+K8 -> 24518.676
B10: CAMARON CRUDO 41-50 0% PORCIONX 7UND PAQUETE POR 10 PORCIONES | C10: uds | D10: 7 | E10: 0 | F10: 7 | G10: =+VLOOKUP(Tabla1103453454455456479108135149[[#This Row],[Ingrediente]],Tabla34[#All],3,0) -> 485.71429 | H10: =+Tabla1103453454455456479108135149[[#This Row],[Costo]]*Tabla1103453454455456479108135149[[#This Row],[Unidades]] -> 3400 | J10: VALOR DE VENTA | K10: 79000
B11: CEBOLLA MORADA LIMPIA | C11: g | D11: 40 | E11: 27 | F11: 54.795 | G11: =+VLOOKUP(Tabla1103453454455456479108135149[[#This Row],[Ingrediente]],Tabla34[#All],3,0) -> 3.8 | H11: =+Tabla1103453454455456479108135149[[#This Row],[Costo]]*Tabla1103453454455456479108135149[[#This Row],[Unidades]] -> 208.221 | J11: IPOCONSUMO | K11: =+K10/1.08*0.08 -> 5851.8519
B12: CILANTRO LIMPIO X KILO | C12: g | D12: 3 | E12: 40 | F12: 5 | G12: =+VLOOKUP(Tabla1103453454455456479108135149[[#This Row],[Ingrediente]],Tabla34[#All],3,0) -> 5.5 | H12: =+Tabla1103453454455456479108135149[[#This Row],[Costo]]*Tabla1103453454455456479108135149[[#This Row],[Unidades]] -> 27.5 | J12: VALOR ANTES DE IPO | K12: =+K10-K11 -> 73148.148
B13: FILETE DE TILAPIA FRESCA LO | C13: g | D13: 150 | E13: 10 | F13: 166.667 | G13: =+VLOOKUP(Tabla1103453454455456479108135149[[#This Row],[Ingrediente]],Tabla34[#All],3,0) -> 37 | H13: =+Tabla1103453454455456479108135149[[#This Row],[Costo]]*Tabla1103453454455456479108135149[[#This Row],[Unidades]] -> 6166.679 | J13: MARGEN. | K13: =+K9/K12 -> 0.33519203
B14: MAIZ TIERNO METOO VACUMX 340G DRE 285G | C14: g | D14: 24 | E14: 0 | F14: 24 | G14: =+VLOOKUP(Tabla1103453454455456479108135149[[#This Row],[Ingrediente]],Tabla34[#All],3,0) -> 21.754386 | H14: =+Tabla1103453454455456479108135149[[#This Row],[Costo]]*Tabla1103453454455456479108135149[[#This Row],[Unidades]] -> 522.10526 | J14: GANANCIA | K14: =+K12-K9 -> 48629.472
B15: PAPA CRIOLLA BALIN O CHIRIYA | C15: g | D15: 150 | E15: 5 | F15: 157.895 | G15: =+VLOOKUP(Tabla1103453454455456479108135149[[#This Row],[Ingrediente]],Tabla34[#All],3,0) -> 4.5 | H15: =+Tabla1103453454455456479108135149[[#This Row],[Costo]]*Tabla1103453454455456479108135149[[#This Row],[Unidades]] -> 710.5275 | J15: MARGEN PORCENTUAL | K15: =+K14/K9 -> 1.9833645
B16: SALSA DE SOYA X 2O LITROS | C16: g | D16: 10 | E16: 0 | F16: 10 | G16: =+VLOOKUP(Tabla1103453454455456479108135149[[#This Row],[Ingrediente]],Tabla34[#All],3,0) -> 8.925 | H16: =+Tabla1103453454455456479108135149[[#This Row],[Costo]]*Tabla1103453454455456479108135149[[#This Row],[Unidades]] -> 89.25
B17: SUB. CHIPS DE YUCA | C17: g | D17: 40 | E17: 0 | F17: 40 | G17: =+VLOOKUP(Tabla1103453454455456479108135149[[#This Row],[Ingrediente]],Tabla34[#All],3,0) -> 11.478188 | H17: =+Tabla1103453454455456479108135149[[#This Row],[Costo]]*Tabla1103453454455456479108135149[[#This Row],[Unidades]] -> 459.12754
B18: SUB. PULPO MEXICANO (ROCOTO)*150G | C18: uds | D18: 0.4 | E18: 0 | F18: 0.4 | G18: =+VLOOKUP(Tabla1103453454455456479108135149[[#This Row],[Ingrediente]],Tabla34[#All],3,0) -> 20955.187 | H18: =+Tabla1103453454455456479108135149[[#This Row],[Costo]]*Tabla1103453454455456479108135149[[#This Row],[Unidades]] -> 8382.0749
B19: SUB. SALSA DE CHICHARRONES | C19: g | D19: 100 | E19: 0 | F19: 100 | G19: =+VLOOKUP(Tabla1103453454455456479108135149[[#This Row],[Ingrediente]],Tabla34[#All],3,0) -> 17.685474 | H19: =+Tabla1103453454455456479108135149[[#This Row],[Costo]]*Tabla1103453454455456479108135149[[#This Row],[Unidades]] -> 1768.5474 | K19: =50/150 -> 0.33333333
H20: =SUBTOTAL(109,Tabla1103453454455456479108135149[Total costo]) -> 23351.12
J21: ANALISIS RECETA
B22: CEVICHE ROCOTO | J22: COSTO DEL PLATO | K22: =SUM(Tabla1103453454455456479108130137151[Total costo]) -> 15762.335
B23: Ingrediente | C23: Und | D23: Unidades Netas | E23: % Merma | F23: Unidades | G23: Costo | H23: Total costo | J23: MARGEN DE ERROR DEL 5% | K23: =+K22*5% -> 788.11676
B24: AGUACATE CHOCKETTE X KILO | C24: g | D24: 40 | E24: 25 | F24: 53.333 | G24: =+VLOOKUP(Tabla1103453454455456479108130137151[[#This Row],[Ingrediente]],Tabla34[#All],3,0) -> 14 | H24: =+Tabla1103453454455456479108130137151[[#This Row],[Costo]]*Tabla1103453454455456479108130137151[[#This Row],[Unidades]] -> 746.662 | J24: COSTO + MARGEN ERROR | K24: =+K22+K23 -> 16550.452
B25: AJI DULCE X KILO | C25: g | D25: 2 | E25: 10 | F25: 2.222 | G25: =+VLOOKUP(Tabla1103453454455456479108130137151[[#This Row],[Ingrediente]],Tabla34[#All],3,0) -> 8 | H25: =+Tabla1103453454455456479108130137151[[#This Row],[Costo]]*Tabla1103453454455456479108130137151[[#This Row],[Unidades]] -> 17.776 | J25: VALOR DE VENTA | K25: 62000
